Workbook
Name UPD: 'Email Template'!$K$7:$W$40
Name EOS_DeliverySuccess: 'DSP RTS RETURNS '!$C$3:$R$6
Name UPD: #REF!

Sheet Form Responses 1
A1: Timestamp | B1: Untitled Question

Sheet DSP RTS RETURNS 
A1: QDCI DVC 4 | C1: (UTA= Unable To Access)(BC= Business Closed) (FDD= Future Delivery Date) (REJ= Rejected) (Locker Full) (NSL= No Secure Location) (UTL= Unable To Locate) (OODT= Out Of Drive Time/ Missort/Extra) (Missing= Not on Van)
C3: PKGS DISPATCHED | D3: ACTUAL DISPATCHED | E3: PKGS DELIVERED | F3: DELIVERED % | G3: Return % | H3: PKGS RETURNED | I3: UTA | J3: BC | K3: FDD | L3: REJ./ DAMAGED | M3: LOCKER FULL | N3: NSL | O3: UTL | P3: EXTRA | R3: MISSING
A4: CORE - 10:05AM WAVE | C4: =C35 -> 5093 | D4: =D35 -> 5092 | E4: =E35 -> 5034 | F4: =E4/C4 -> 0.98841547 | G4: =(H4/C4) -> 0.01138818 | H4: =SUM(I4:P4) -> 58 | I4: =I35 -> 32 | J4: =J35 -> 17 | K4: =K35 -> 0 | L4: =L35 -> 3 | M4: =M35 -> 1 | N4: =N35 -> 0 | O4: =O35 -> 5 | P4: =P35 -> 0 | R4: =R35 -> 1 | W4: 10:05 AM WAVE | Y4: =Y35 -> 0.39259259
A5: CORE TOTAL: | C5: =SUM(C4) -> 5093 | D5: =SUM(D4) -> 5092 | E5: =SUM(E4) -> 5034 | F5: =(E5/C5) -> 0.98841547 | G5: =(H5/C5) -> 0.01138818 | H5: =SUM(H4) -> 58 | I5: =SUM(I4) -> 32 | J5: =SUM(J4) -> 17 | K5: =SUM(K4) -> 0 | L5: =SUM(L4) -> 3 | M5: =SUM(M4) -> 1 | N5: =SUM(N4) -> 0 | O5: =SUM(O4) -> 5 | P5: =SUM(P4) -> 0 | R5: =SUM(R4) -> 1
I6: =I5/$H$5 -> 0.55172414 | J6: =J5/$H$5 -> 0.29310345 | K6: =K5/$H$5 -> 0 | L6: =L5/$H$5 -> 0.051724138 | M6: =M5/$H$5 -> 0.017241379 | N6: =N5/$H$5 -> 0 | O6: =O5/$H$5 -> 0.086206897 | P6: =P5/$H$5 -> 0
A8: ABOVE Chart is Automated, don't enter values manually | T8: ABOVE Chart is Automated, don't enter values manually
T10: Planned (Manifest) | W10: Actual | AA10: Time Arrived at Station | AB10: Rescued? Y/N | AC10: RABBIT # | AD10: Van # | AE10: AMZL KEYS GIVEN | AF10: AMZL KEYS Returned (y/n) | AG10: NOTES
A11: ROUTE # | B11: DELIVERY ASSOCIATE | C11: PKGS DISPATCHED | D11: ACTUAL DISPATCHED | E11: PKGS DELIVERED | F11: DELIVERED % | G11: Return % | H11: PKGS RETURNED | I11: UTA | J11: BC | K11: FDD | L11: REJ./ DAMAGED | M11: LOCKER FULL | N11: NSL | O11: UTL | P11: EXTRA | R11: MISSING | T11: Start | U11: Finish | V11: Planned Time | W11: Start | X11: Finish | Y11: Actual Time | Z11: Time Difference
A13: AM | B13: DELIVERY ASSOCIATE | C13: Packages Dispatched | D13: ACTUAL Dispatched | E13: Packages Delivered | F13: Delivered % | G13: Return % | H13: PKGS RETURNED | I13: UTA | J13: BC | K13: FDD | L13: Rejected | M13: LOCKER FULL | N13: NSL | O13: UTL | P13: OODT | R13: MISSING | T13: START | U13: FINISH | V13: Planned Time | W13: START | X13: FINISH | Y13: Actual Time | Z13: Time Difference | AB13: Rescued? Y/N | AC13: RABBIT # | AD13: VAN # | AE13: KEYS | AF13: KEYS RETURNED | AG13: NOTES
A14: CX85 | B14: Akash Akash (A3M38Z4NGI9OR3) / QDCI / A3M38Z4NGI9OR3 | C14: 275 | D14: =(C14-R14) -> 275 | E14: =(D14-H14) -> 274 | F14: =(C14-H14)/C14 -> 0.99636364 | G14: =(H14/C14) -> 0.0036363636 | H14: =SUM(I14:P14) -> 1 | O14: 1 | T14: 0.49305556 | U14: 0.77638889 | V14: =U14-T14 -> 0.28333333 | W14: 0.49027778 | X14: 0.88888889 | Y14: =X14-W14 -> 0.39861111
A15: CX84 | B15: Khushdeep Singh Cheema (A2KXEYK2UAQ1SX) / QDCI / A2KXEYK2UAQ1SX | C15: 236 | D15: =(C15-R15) -> 236 | E15: =(D15-H15) -> 236 | F15: =(C15-H15)/C15 -> 1 | G15: =(H15/C15) -> 0 | H15: =SUM(I15:P15) -> 0 | T15: 0.49305556 | U15: 0.84305556 | V15: =U15-T15 -> 0.35 | W15: 0.49027778 | X15: 0.87152778 | Y15: =X15-W15 -> 0.38125
A16: CX86 | B16: Gagandeep Singh Singh (A3959UPAEK7B1W) / QDCI / A3959UPAEK7B1W | C16: 288 | D16: =(C16-R16) -> 288 | E16: =(D16-H16) -> 287 | F16: =(C16-H16)/C16 -> 0.99652778 | G16: =(H16/C16) -> 0.0034722222 | H16: =SUM(I16:P16) -> 1 | O16: 1 | T16: 0.49305556 | U16: 0.75208333 | V16: =U16-T16 -> 0.25902778 | W16: 0.49027778 | X16: 0.875 | Y16: =X16-W16 -> 0.38472222
A17: CX88 | B17: Tarandeep Singh (A33HB7XV71IC7T) / QDCI / A33HB7XV71IC7T | C17: 202 | D17: =(C17-R17) -> 202 | E17: =(D17-H17) -> 201 | F17: =(C17-H17)/C17 -> 0.99504951 | G17: =(H17/C17) -> 0.004950495 | H17: =SUM(I17:P17) -> 1 | O17: 1 | T17: 0.49305556 | U17: 0.83541667 | V17: =U17-T17 -> 0.34236111 | W17: 0.49027778 | X17: 0.88888889 | Y17: =X17-W17 -> 0.39861111
A18: CX83 | B18: Lovepreet Singh (AZULSLRV35N5I) / QDCI / AZULSLRV35N5I | C18: 190 | D18: =(C18-R18) -> 190 | E18: =(D18-H18) -> 189 | F18: =(C18-H18)/C18 -> 0.99473684 | G18: =(H18/C18) -> 0.0052631579 | H18: =SUM(I18:P18) -> 1 | I18: 1 | T18: 0.49305556 | U18: 0.84583333 | V18: =U18-T18 -> 0.35277778 | W18: 0.49027778 | X18: 0.88541667 | Y18: =X18-W18 -> 0.39513889
A19: CX96 | B19: Rahul Mannan (AKF1ZEB0TWD96) / QDCI / AKF1ZEB0TWD96 | C19: 220 | D19: =(C19-R19) -> 220 | E19: =(D19-H19) -> 217 | F19: =(C19-H19)/C19 -> 0.98636364 | G19: =(H19/C19) -> 0.013636364 | H19: =SUM(I19:P19) -> 3 | I19: 3 | T19: 0.49305556 | U19: 0.84791667 | V19: =U19-T19 -> 0.35486111 | W19: 0.49027778 | X19: 0.88888889 | Y19: =X19-W19 -> 0.39861111
A20: CX97 | B20: Pardeep Singh (AU6YIGC7GXQGA) / QDCI / AU6YIGC7GXQGA | C20: 210 | D20: =(C20-R20) -> 210 | E20: =(D20-H20) -> 200 | F20: =(C20-H20)/C20 -> 0.95238095 | G20: =(H20/C20) -> 0.047619048 | H20: =SUM(I20:P20) -> 10 | I20: 9 | O20: 1 | T20: 0.49305556 | U20: 0.84305556 | V20: =U20-T20 -> 0.35 | W20: 0.49027778 | X20: 0.95486111 | Y20: =X20-W20 -> 0.46458333
A21: CX92 | B21: Iqbal Singh (A2WDUOOWN1ORVL) / QDCI / A2WDUOOWN1ORVL | C21: 261 | D21: =(C21-R21) -> 261 | E21: =(D21-H21) -> 260 | F21: =(C21-H21)/C21 -> 0.99616858 | G21: =(H21/C21) -> 0.0038314176 | H21: =SUM(I21:P21) -> 1 | J21: 1 | T21: 0.49305556 | U21: 0.73680556 | V21: =U21-T21 -> 0.24375 | W21: 0.49027778 | X21: 0.875 | Y21: =X21-W21 -> 0.38472222
A22: CX91 | B22: Harmanpreet Singh (AHJWCXI2ORDJY) / QDCI / AHJWCXI2ORDJY | C22: 265 | D22: =(C22-R22) -> 265 | E22: =(D22-H22) -> 262 | F22: =(C22-H22)/C22 -> 0.98867925 | G22: =(H22/C22) -> 0.011320755 | H22: =SUM(I22:P22) -> 3 | J22: 3 | T22: 0.49305556 | U22: 0.79722222 | V22: =U22-T22 -> 0.30416667 | W22: 0.49027778 | X22: 0.88541667 | Y22: =X22-W22 -> 0.39513889
A23: CX93 | B23: Vishal Chaudhary (A7FWBKAGXA5LK) / QDCI / A7FWBKAGXA5LK | C23: 258 | D23: =(C23-R23) -> 258 | E23: =(D23-H23) -> 258 | F23: =(C23-H23)/C23 -> 1 | G23: =(H23/C23) -> 0 | H23: =SUM(I23:P23) -> 0 | T23: 0.49305556 | U23: 0.80763889 | V23: =U23-T23 -> 0.31458333 | W23: 0.49027778 | X23: 0.88541667 | Y23: =X23-W23 -> 0.39513889
A24: CX101 | B24: Mehakpreet Singh (A3RO6BBCA3NOYM) / QDCI / A3RO6BBCA3NOYM | C24: 260 | D24: =(C24-R24) -> 260 | E24: =(D24-H24) -> 255 | F24: =(C24-H24)/C24 -> 0.98076923 | G24: =(H24/C24) -> 0.019230769 | H24: =SUM(I24:P24) -> 5 | J24: 5 | T24: 0.49305556 | U24: 0.80486111 | V24: =U24-T24 -> 0.31180556 | W24: 0.49027778 | X24: 0.88541667 | Y24: =X24-W24 -> 0.39513889
A25: CX87 | B25: Sikander Singh (A4KU9LEU82OTF) / QDCI / A4KU9LEU82OTF | C25: 301 | D25: =(C25-R25) -> 301 | E25: =(D25-H25) -> 301 | F25: =(C25-H25)/C25 -> 1 | G25: =(H25/C25) -> 0 | H25: =SUM(I25:P25) -> 0 | T25: 0.49652778 | U25: 0.76180556 | V25: =U25-T25 -> 0.26527778 | W25: 0.49166667 | X25: 0.86805556 | Y25: =X25-W25 -> 0.37638889
A26: CX89 | B26: Rompal Singh Hayer (A3QZGAMB5M5IK0) / QDCI / A3QZGAMB5M5IK0 | C26: 230 | D26: =(C26-R26) -> 230 | E26: =(D26-H26) -> 229 | F26: =(C26-H26)/C26 -> 0.99565217 | G26: =(H26/C26) -> 0.0043478261 | H26: =SUM(I26:P26) -> 1 | I26: 1 | T26: 0.49652778 | U26: 0.85208333 | V26: =U26-T26 -> 0.35555556 | W26: 0.49166667 | X26: 0.92361111 | Y26: =X26-W26 -> 0.43194444
A27: CX95 | B27: Lovepreet Singh Bassi (A2SCS728PUCGTE) / QDCI / A2SCS728PUCGTE | C27: 243 | D27: =(C27-R27) -> 243 | E27: =(D27-H27) -> 230 | F27: =(C27-H27)/C27 -> 0.94650206 | G27: =(H27/C27) -> 0.053497942 | H27: =SUM(I27:P27) -> 13 | I27: 12 | J27: 1 | T27: 0.49652778 | U27: 0.82430556 | V27: =U27-T27 -> 0.32777778 | W27: 0.49166667 | X27: 0.90972222 | Y27: =X27-W27 -> 0.41805556
A28: CX98 | B28: Amritpal Singh (A1JSQIK4OD79DV) / QDCI / A1JSQIK4OD79DV | C28: 254 | D28: =(C28-R28) -> 254 | E28: =(D28-H28) -> 252 | F28: =(C28-H28)/C28 -> 0.99212598 | G28: =(H28/C28) -> 0.0078740157 | H28: =SUM(I28:P28) -> 2 | I28: 1 | J28: 1 | T28: 0.49652778 | U28: 0.8 | V28: =U28-T28 -> 0.30347222 | W28: 0.49166667 | X28: 0.86805556 | Y28: =X28-W28 -> 0.37638889
A29: CX99 | B29: Gurdas Singh Sidhu (AGOU3M5WUIHWC) / QDCI / AGOU3M5WUIHWC | C29: 237 | D29: =(C29-R29) -> 237 | E29: =(D29-H29) -> 228 | F29: =(C29-H29)/C29 -> 0.96202532 | G29: =(H29/C29) -> 0.037974684 | H29: =SUM(I29:P29) -> 9 | I29: 3 | J29: 4 | L29: 2 | T29: 0.49652778 | U29: 0.82777778 | V29: =U29-T29 -> 0.33125 | W29: 0.49166667 | X29: 0.88194444 | Y29: =X29-W29 -> 0.39027778
A30: CX90 | B30: Jagraj Singh (A3NLLQPB0L46N9) / QDCI / A3NLLQPB0L46N9 | C30: 273 | D30: =(C30-R30) -> 273 | E30: =(D30-H30) -> 271 | F30: =(C30-H30)/C30 -> 0.99267399 | G30: =(H30/C30) -> 0.0073260073 | H30: =SUM(I30:P30) -> 2 | I30: 1 | O30: 1 | T30: 0.49652778 | U30: 0.79166667 | V30: =U30-T30 -> 0.29513889 | W30: 0.49166667 | X30: 0.88541667 | Y30: =X30-W30 -> 0.39375
A31: CX94 | B31: Harnamanpreet Singh (A3M45AZWH3K5F3) / QDCI / A3M45AZWH3K5F3 | C31: 268 | D31: =(C31-R31) -> 268 | E31: =(D31-H31) -> 268 | F31: =(C31-H31)/C31 -> 1 | G31: =(H31/C31) -> 0 | H31: =SUM(I31:P31) -> 0 | T31: 0.49652778 | U31: 0.78125 | V31: =U31-T31 -> 0.28472222 | W31: 0.49166667 | X31: 0.88541667 | Y31: =X31-W31 -> 0.39375
A32: CX102 | B32: Sukhwinder Singh (AYLV43T35EAIN) / QDCI / AYLV43T35EAIN | C32: 307 | D32: =(C32-R32) -> 307 | E32: =(D32-H32) -> 306 | F32: =(C32-H32)/C32 -> 0.99674267 | G32: =(H32/C32) -> 0.003257329 | H32: =SUM(I32:P32) -> 1 | M32: 1 | T32: 0.49652778 | U32: 0.76944444 | V32: =U32-T32 -> 0.27291667 | W32: 0.49166667 | X32: 0.88888889 | Y32: =X32-W32 -> 0.39722222
A33: CX100 | B33: Paramjit Gherha (A1NJLYPMMEKHLK) / QDCI / A1NJLYPMMEKHLK | C33: 256 | D33: =(C33-R33) -> 255 | E33: =(D33-H33) -> 253 | F33: =(C33-H33)/C33 -> 0.9921875 | G33: =(H33/C33) -> 0.0078125 | H33: =SUM(I33:P33) -> 2 | J33: 2 | R33: 1 | T33: 0.49652778 | U33: 0.77569444 | V33: =U33-T33 -> 0.27916667 | W33: 0.49166667 | X33: 0.85416667 | Y33: =X33-W33 -> 0.3625
A34: SB36,37 | B34: Karanveer Singh (A34WEHEN1XXRKR) / QDCI / A34WEHEN1XXRKR | C34: 59 | D34: =(C34-R34) -> 59 | E34: =(D34-H34) -> 57 | F34: =(C34-H34)/C34 -> 0.96610169 | G34: =(H34/C34) -> 0.033898305 | H34: =SUM(I34:P34) -> 2 | I34: 1 | L34: 1 | T34: 0.29166667 | U34: 0.38333333 | V34: =U34-T34 -> 0.091666667 | W34: 0.45833333 | X34: 0.77083333 | Y34: =X34-W34 -> 0.3125
C35: =SUM(C14:C34) -> 5093 | D35: =SUM(D14:D34) -> 5092 | E35: =SUM(E14:E34) -> 5034 | I35: =SUM(I14:I34) -> 32 | J35: =SUM(J14:J34) -> 17 | K35: =SUM(K14:K34) -> 0 | L35: =SUM(L14:L34) -> 3 | M35: =SUM(M14:M34) -> 1 | N35: =SUM(N14:N34) -> 0 | O35: =SUM(O14:O34) -> 5 | P35: =SUM(P14:P34) -> 0 | ... R35: =SUM(R14:R34) -> 1 | Y35: =AVERAGEIF(Y14:Y34,"<>0") -> 0.39259259

Sheet AMZL USE
B1: AMZL USE ONLY
B2: CORE | Z2: SAME DAY | AX2: DEVICE Inventory | BI2: AVERAGE TIME
B3: PKGS DISPATCHED | C3: ACTUAL DISPATCHED | D3: PKGS DELIVERED | E3: DELIVERED % | F3: Return % | G3: PKGS RETURNED | H3: UTA | I3: BC | J3: FDD | K3: REJ./ DAMAGED | L3: LOCKER FULL | M3: NSL | N3: UTL | O3: OODT/ EXTRA | Q3: MISSING | R3: Total packages dispatched | S3: TOTAL RETURNED | T3: TOTAL DELIVERED | U3: % RETURNED | V3: # OF ROUTES PLANNED | W3: ACTUAL # OF ROUTES | X3: RESCUE ROUTES GRANTED | Y3: ROUTES DROPPED | Z3: PKGS DISPATCHED | AA3: ACTUAL DISPATCHED | AB3: PKGS DELIVERED | AC3: DELIVERED % | AD3: Return % | AE3: PKGS RETURNED | AF3: UTA | AG3: BC | AH3: FDD | AI3: REJ./ DAMAGED | AJ3: LOCKER FULL | AK3: NSL | AL3: UTL | AM3: OODT/ EXTRA | AO3: MISSING | AP3: Total packages dispatched | AQ3: TOTAL RETURNED | AR3: TOTAL DELIVERED | AS3: % RETURNED | AT3: # OF ROUTES PLANNED | AU3: ACTUAL # OF ROUTES | AV3: RESCUE ROUTES GRANTED | AW3: ROUTES DROPPED | AX3: DSP | AY3: Original | AZ3: Current | BA3: Details | BB3: Borrowed | BC3: Returned | BD3: TOTAL ROUTES RESCUED | BE3: TOTAL TIME UNPLANNED DELAY | BF3: TOTAL PKGS REPORTED MISSING | BG3: TOTAL EXTRA PKGS REPORTED | BH3: 11 AM ROUTES | BI3: CORE AM | BJ3: CORE 11 AM | BK3: SAME DAY
B4: ='DSP RTS RETURNS '!C5 -> 5093 | C4: ='DSP RTS RETURNS '!D5 -> 5092 | D4: ='DSP RTS RETURNS '!E5 -> 5034 | E4: ='DSP RTS RETURNS '!F5 -> 0.98841547 | F4: ='DSP RTS RETURNS '!G5 -> 0.01138818 | G4: ='DSP RTS RETURNS '!H5 -> 58 | H4: ='DSP RTS RETURNS '!I5 -> 32 | I4: ='DSP RTS RETURNS '!J5 -> 17 | ... O4: ='DSP RTS RETURNS '!P5 -> 0 | Q4: ='DSP RTS RETURNS '!R5 -> 1 | R4: ='DSP EOS REPORT'!C4 -> #REF! | S4: ='DSP EOS REPORT'!C5 -> #REF! | T4: ='DSP EOS REPORT'!C6 -> #REF! | U4: ='DSP EOS REPORT'!C7 -> #REF! | V4: ='DSP EOS REPORT'!F4 -> #REF! | W4: ='DSP EOS REPORT'!F5 -> #REF! | X4: ='DSP EOS REPORT'!F6 -> #REF! | Y4: ='DSP EOS REPORT'!F7 -> #REF! | Z4: =#REF! -> #REF! | AA4: =#REF! -> #REF! | AB4: =#REF! -> #REF! | AC4: =#REF! -> #REF! | AD4: =#REF! -> #REF! | AE4: =#REF! -> #REF! | AF4: =#REF! -> #REF! | AG4: =#REF! -> #REF! | ... AM4: =#REF! -> #REF! | AO4: =#REF! -> #REF! | AP4: ='DSP EOS REPORT'!L4 -> #REF! | AQ4: ='DSP EOS REPORT'!L5 -> #REF! | AR4: ='DSP EOS REPORT'!L6 -> #REF! | AS4: ='DSP EOS REPORT'!L7 -> #REF! | AT4: ='DSP EOS REPORT'!S4 -> #REF! | AU4: ='DSP EOS REPORT'!S5 -> #REF! | AV4: ='DSP EOS REPORT'!S6 -> #REF! | AW4: ='DSP EOS REPORT'!S7 -> #REF! | AX4: ='DSP EOS REPORT'!W4 -> #REF! | AY4: ='DSP EOS REPORT'!X4 -> #REF! | AZ4: ='DSP EOS REPORT'!Y4 -> #REF! | BA4: ='DSP EOS REPORT'!Z4 -> #REF! | BB4: ='DSP EOS REPORT'!AG4 -> #REF! | BC4: ='DSP EOS REPORT'!AH4 -> #REF! | BD4: ='DSP EOS REPORT'!I12 -> #REF! | BE4: ='DSP EOS REPORT'!S39 -> #REF! | BF4: ='DSP EOS REPORT'!Y11 -> #REF! | BG4: ='DSP EOS REPORT'!AG11 -> #REF! | BH4: ='DSP EOS REPORT'!C10 -> #REF! | BI4: ='DSP RTS RETURNS '!Y4 -> 0.39259259 | BJ4: =#REF! -> #REF! | BK4: =#REF! -> #REF!

Sheet Email Template
B1: Email template | D1: Copy & Paste into Email and send to AMZL Ops & Mgmt. | K1: EOS - UPD Submission | Q1: Key: | R1: =IFERROR(__xludf.DUMMYFUNCTION("vlookup(#REF!,IMPORTRANGE(""1kqI6asRipbwu55xhdhQlPSvL1rwTNgLkpaVfuldGzJs"",""Google Keys!A2:B""),2,false)"),"#REF!") -> #REF!
B4: DELE - DVC6 EOS Summary | H4: =TODAY() -> 46106 | K4: UPD Tracker | Q4: Link to UPD Portal | R4: =HYPERLINK("https://amazon88.au1.qualtrics.com/jfe/form/SV_b9grRQdIJSW4W2N","Here") -> Here | V4: Primary DSP email for submitting:
B5: Route Overview | D5: Delivery Success | H5: Returns | N5: Has the UPD been submitted: | O5: No | Q5: Submitted by:
B6: Total Routes Actual | C6: - | D6: PKGS Dispatched | G6: =IFERROR(HLOOKUP($D6,EOS_DeliverySuccess,4,0),0) | H6: UTA | I6: =IFERROR(HLOOKUP($H6,EOS_DeliverySuccess,4,0),0) -> 0.55172414 | K6: Wave | L6: C: | M6: 0.42013889 | R6: Total Routes with approved UPD: | S6: =COUNTIF(U9:U46,TRUE) -> 0 | U6: UPD Min: | V6: =sumif(U9:U46,TRUE,V9:V46) -> 0
B7: Total Routes Scheduled | C7: - | D7: PKGS Delivered | G7: =IFERROR(HLOOKUP($D7,EOS_DeliverySuccess,4,0),0) | H7: BC | I7: =IFERROR(HLOOKUP($H7,EOS_DeliverySuccess,4,0),0) -> 0.29310345 | K7: C/11 | L7: Delivery Associate | P7: Route | Q7: Wave | R7: RTS | S7: AMZL Hours | T7: ADD to EOS Report | U7: Claim UPD? | V7: > 600 MIN | W7: Reason Why DA went over 600 min
B8: Routes Cancelled (AMZL) | C8: - | D8: PKGS Returned | G8: =IFERROR(HLOOKUP($D8,EOS_DeliverySuccess,4,0),0) | H8: FDD | I8: =IFERROR(HLOOKUP($H8,EOS_DeliverySuccess,4,0),0) -> 0 | K8: C | P8: {=IFERROR(INDEX('DSP RTS RETURNS '!A$14:A$38,MATCH(L8,'DSP RTS RETURNS '!B$14:B$38,0)),"")} | R8: {=IFERROR(INDEX('DSP RTS RETURNS '!AA$14:AA$38,MATCH(L8,'DSP RTS RETURNS '!B$14:B$38,0)),"")} | S8: =R8-Q8 -> 0 | T8: FALSE | V8: =IF(S8 > "10:30" + TIME(0,0,0),S8 - "10:30","")
B9: Routes Dropped (DSP) | C9: - | D9: Return % | G9: =IFERROR(HLOOKUP($D9,EOS_DeliverySuccess,4,0),0) | H9: REJ./ DAMAGED | I9: =IFERROR(HLOOKUP($H9,EOS_DeliverySuccess,4,0),0) -> 0.051724138 | K9: C | P9: {=IFERROR(INDEX('DSP RTS RETURNS '!A$14:A$38,MATCH(L9,'DSP RTS RETURNS '!B$14:B$38,0)),"")} | R9: {=IFERROR(INDEX('DSP RTS RETURNS '!AA$14:AA$38,MATCH(L9,'DSP RTS RETURNS '!B$14:B$38,0)),"")} | S9: =R9-Q9 -> 0 | T9: FALSE | V9: =IF(S9 > "10:30" + TIME(0,0,0),S9 - "10:30","")
B10: Routes QC (Pick-up) | C10: - | D10: Average SPR | G10: =G6/C6 -> #VALUE! | H10: LOCKER FULL | I10: =IFERROR(HLOOKUP($H10,EOS_DeliverySuccess,4,0),0) -> 0.017241379 | K10: C | P10: {=IFERROR(INDEX('DSP RTS RETURNS '!A$14:A$38,MATCH(L10,'DSP RTS RETURNS '!B$14:B$38,0)),"")} | R10: {=IFERROR(INDEX('DSP RTS RETURNS '!AA$14:AA$38,MATCH(L10,'DSP RTS RETURNS '!B$14:B$38,0)),"")} | S10: =R10-Q10 -> 0 | T10: FALSE | V10: =IF(S10 > "10:30" + TIME(0,0,0),S10 - "10:30","")
B11: Routes offered | C11: - | D11: Avg. Time (1st Attempts) | G11: ='DSP RTS RETURNS '!Y4 -> 0.39259259 | H11: NSL | I11: =IFERROR(HLOOKUP($H11,EOS_DeliverySuccess,4,0),0) -> 0 | K11: C | P11: {=IFERROR(INDEX('DSP RTS RETURNS '!A$14:A$38,MATCH(L11,'DSP RTS RETURNS '!B$14:B$38,0)),"")} | R11: {=IFERROR(INDEX('DSP RTS RETURNS '!AA$14:AA$38,MATCH(L11,'DSP RTS RETURNS '!B$14:B$38,0)),"")} | S11: =R11-Q11 -> 0 | T11: FALSE | U11: FALSE | V11: =IF(S11 > "10:30" + TIME(0,0,0),S11 - "10:30","")
B12: AMZL Device Report | D12: AMZL Apartment Key/Fob Report | H12: UTL | I12: =IFERROR(HLOOKUP($H12,EOS_DeliverySuccess,4,0),0) -> 0.086206897 | K12: C | P12: {=IFERROR(INDEX('DSP RTS RETURNS '!A$14:A$38,MATCH(L12,'DSP RTS RETURNS '!B$14:B$38,0)),"")} | R12: {=IFERROR(INDEX('DSP RTS RETURNS '!AA$14:AA$38,MATCH(L12,'DSP RTS RETURNS '!B$14:B$38,0)),"")} | S12: =R12-Q12 -> 0 | T12: FALSE | U12: FALSE | V12: =IF(S12 > "10:30" + TIME(0,0,0),S12 - "10:30","")
B13: Rabbits Borrowed | C13: 0 | D13: AMZL Keys Out | F13: N/A | H13: OODT/ EXTRA | I13: =IFERROR(HLOOKUP($H13,EOS_DeliverySuccess,4,0),0) -> 0 | K13: C | P13: {=IFERROR(INDEX('DSP RTS RETURNS '!A$14:A$38,MATCH(L13,'DSP RTS RETURNS '!B$14:B$38,0)),"")} | R13: {=IFERROR(INDEX('DSP RTS RETURNS '!AA$14:AA$38,MATCH(L13,'DSP RTS RETURNS '!B$14:B$38,0)),"")} | S13: =R13-Q13 -> 0 | T13: FALSE | U13: FALSE | V13: =IF(S13 > "10:30" + TIME(0,0,0),S13 - "10:30","")
B14: Rabbits Returned | C14: 0 | D14: AMZL Keys In | F14: N/A | H14: Missing | I14: =IFERROR(HLOOKUP($H14,EOS_DeliverySuccess,4,0),0) | K14: C | P14: {=IFERROR(INDEX('DSP RTS RETURNS '!A$14:A$38,MATCH(L14,'DSP RTS RETURNS '!B$14:B$38,0)),"")} | R14: {=IFERROR(INDEX('DSP RTS RETURNS '!AA$14:AA$38,MATCH(L14,'DSP RTS RETURNS '!B$14:B$38,0)),"")} | S14: =R14-Q14 -> 0 | T14: FALSE | U14: FALSE | V14: =IF(S14 > "10:30" + TIME(0,0,0),S14 - "10:30","")
B15: Nursery Level 1 Added (IF ANY) | C15: FALSE | D15: Nursery Level 2 Added (IF ANY) | G15: FALSE | H15: On Call Added for C1 and C2 (IF ANY) | I15: FALSE | K15: C | S15: =R15-Q15 -> 0 | T15: FALSE
B16: DA over 600 min | K16: C | P16: {=IFERROR(INDEX('DSP RTS RETURNS '!A$14:A$38,MATCH(L16,'DSP RTS RETURNS '!B$14:B$38,0)),"")} | R16: {=IFERROR(INDEX('DSP RTS RETURNS '!AA$14:AA$38,MATCH(L16,'DSP RTS RETURNS '!B$14:B$38,0)),"")} | S16: =R16-Q16 -> 0 | T16: FALSE | U16: FALSE | V16: =IF(S16 > "10:30" + TIME(0,0,0),S16 - "10:30","")
B17: Delivery Associate | D17: Route | E17: Min | F17: Reason | K17: C | P17: {=IFERROR(INDEX('DSP RTS RETURNS '!A$14:A$38,MATCH(L17,'DSP RTS RETURNS '!B$14:B$38,0)),"")} | R17: {=IFERROR(INDEX('DSP RTS RETURNS '!AA$14:AA$38,MATCH(L17,'DSP RTS RETURNS '!B$14:B$38,0)),"")} | S17: =R17-Q17 -> 0 | T17: FALSE | U17: FALSE | V17: =IF(S17 > "10:30" + TIME(0,0,0),S17 - "10:30","")
B18: =IFERROR(__xludf.DUMMYFUNCTION("query(K8:W72, ""SELECT L WHERE T = TRUE"")"),"#N/A") -> #N/A | D18: {=IFERROR(INDEX('Email Template'!P$8:P$72,MATCH(B18,'Email Template'!L$8:L$72,0)),"")} | E18: =IFERROR(INDEX(V$8:V$72,MATCH(B18,L$8:L$72,0)),"") | F18: =IFERROR(INDEX(W$8:W$72,MATCH(B18,L$8:L$72,0)),"") | K18: C | P18: {=IFERROR(INDEX('DSP RTS RETURNS '!A$14:A$38,MATCH(L18,'DSP RTS RETURNS '!B$14:B$38,0)),"")} | R18: {=IFERROR(INDEX('DSP RTS RETURNS '!AA$14:AA$38,MATCH(L18,'DSP RTS RETURNS '!B$14:B$38,0)),"")} | S18: =R18-Q18 -> 0 | T18: FALSE | U18: FALSE | V18: =IF(S18 > "10:30" + TIME(0,0,0),S18 - "10:30","")
D19: {=IFERROR(INDEX('Email Template'!P$8:P$72,MATCH(B19,'Email Template'!L$8:L$72,0)),"")} | E19: =IFERROR(INDEX(V$8:V$72,MATCH(B19,L$8:L$72,0)),"") | F19: =IFERROR(INDEX(W$8:W$72,MATCH(B19,L$8:L$72,0)),"") | K19: C | P19: {=IFERROR(INDEX('DSP RTS RETURNS '!A$14:A$38,MATCH(L19,'DSP RTS RETURNS '!B$14:B$38,0)),"")} | R19: {=IFERROR(INDEX('DSP RTS RETURNS '!AA$14:AA$38,MATCH(L19,'DSP RTS RETURNS '!B$14:B$38,0)),"")} | S19: =R19-Q19 -> 0 | T19: FALSE | U19: FALSE | V19: =IF(S19 > "10:30" + TIME(0,0,0),S19 - "10:30","")
D20: {=IFERROR(INDEX('Email Template'!P$8:P$72,MATCH(B20,'Email Template'!L$8:L$72,0)),"")} | E20: =IFERROR(INDEX(V$8:V$72,MATCH(B20,L$8:L$72,0)),"") | F20: =IFERROR(INDEX(W$8:W$72,MATCH(B20,L$8:L$72,0)),"") | K20: C | P20: {=IFERROR(INDEX('DSP RTS RETURNS '!A$14:A$38,MATCH(L20,'DSP RTS RETURNS '!B$14:B$38,0)),"")} | R20: {=IFERROR(INDEX('DSP RTS RETURNS '!AA$14:AA$38,MATCH(L20,'DSP RTS RETURNS '!B$14:B$38,0)),"")} | S20: =R20-Q20 -> 0 | T20: FALSE | U20: FALSE | V20: =IF(S20 > "10:30" + TIME(0,0,0),S20 - "10:30","")
D21: {=IFERROR(INDEX('Email Template'!P$8:P$72,MATCH(B21,'Email Template'!L$8:L$72,0)),"")} | E21: =IFERROR(INDEX(V$8:V$72,MATCH(B21,L$8:L$72,0)),"") | F21: =IFERROR(INDEX(W$8:W$72,MATCH(B21,L$8:L$72,0)),"") | K21: C | P21: {=IFERROR(INDEX('DSP RTS RETURNS '!A$14:A$38,MATCH(L21,'DSP RTS RETURNS '!B$14:B$38,0)),"")} | R21: {=IFERROR(INDEX('DSP RTS RETURNS '!AA$14:AA$38,MATCH(L21,'DSP RTS RETURNS '!B$14:B$38,0)),"")} | S21: =R21-Q21 -> 0 | T21: FALSE | U21: FALSE | V21: =IF(S21 > "10:30" + TIME(0,0,0),S21 - "10:30","")
D22: {=IFERROR(INDEX('Email Template'!P$8:P$72,MATCH(B22,'Email Template'!L$8:L$72,0)),"")} | E22: =IFERROR(INDEX(V$8:V$72,MATCH(B22,L$8:L$72,0)),"") | F22: =IFERROR(INDEX(W$8:W$72,MATCH(B22,L$8:L$72,0)),"") | K22: C | P22: {=IFERROR(INDEX('DSP RTS RETURNS '!A$14:A$38,MATCH(L22,'DSP RTS RETURNS '!B$14:B$38,0)),"")} | R22: {=IFERROR(INDEX('DSP RTS RETURNS '!AA$14:AA$38,MATCH(L22,'DSP RTS RETURNS '!B$14:B$38,0)),"")} | S22: =R22-Q22 -> 0 | T22: FALSE | U22: FALSE | V22: =IF(S22 > "10:30" + TIME(0,0,0),S22 - "10:30","")
D23: {=IFERROR(INDEX('Email Template'!P$8:P$72,MATCH(B23,'Email Template'!L$8:L$72,0)),"")} | E23: =IFERROR(INDEX(V$8:V$72,MATCH(B23,L$8:L$72,0)),"") | F23: =IFERROR(INDEX(W$8:W$72,MATCH(B23,L$8:L$72,0)),"") | K23: C | P23: {=IFERROR(INDEX('DSP RTS RETURNS '!A$14:A$38,MATCH(L23,'DSP RTS RETURNS '!B$14:B$38,0)),"")} | R23: {=IFERROR(INDEX('DSP RTS RETURNS '!AA$14:AA$38,MATCH(L23,'DSP RTS RETURNS '!B$14:B$38,0)),"")} | S23: =R23-Q23 -> 0 | T23: FALSE | U23: FALSE | V23: =IF(S23 > "10:30" + TIME(0,0,0),S23 - "10:30","")
D24: {=IFERROR(INDEX('Email Template'!P$8:P$72,MATCH(B24,'Email Template'!L$8:L$72,0)),"")} | E24: =IFERROR(INDEX(V$8:V$72,MATCH(B24,L$8:L$72,0)),"") | F24: =IFERROR(INDEX(W$8:W$72,MATCH(B24,L$8:L$72,0)),"") | K24: C | P24: {=IFERROR(INDEX('DSP RTS RETURNS '!A$14:A$38,MATCH(L24,'DSP RTS RETURNS '!B$14:B$38,0)),"")} | R24: {=IFERROR(INDEX('DSP RTS RETURNS '!AA$14:AA$38,MATCH(L24,'DSP RTS RETURNS '!B$14:B$38,0)),"")} | S24: =R24-Q24 -> 0 | T24: FALSE | U24: FALSE | V24: =IF(S24 > "10:30" + TIME(0,0,0),S24 - "10:30","")
D25: {=IFERROR(INDEX('Email Template'!P$8:P$72,MATCH(B25,'Email Template'!L$8:L$72,0)),"")} | E25: =IFERROR(INDEX(V$8:V$72,MATCH(B25,L$8:L$72,0)),"") | F25: =IFERROR(INDEX(W$8:W$72,MATCH(B25,L$8:L$72,0)),"") | K25: C | P25: {=IFERROR(INDEX('DSP RTS RETURNS '!A$14:A$38,MATCH(L25,'DSP RTS RETURNS '!B$14:B$38,0)),"")} | R25: {=IFERROR(INDEX('DSP RTS RETURNS '!AA$14:AA$38,MATCH(L25,'DSP RTS RETURNS '!B$14:B$38,0)),"")} | S25: =R25-Q25 -> 0 | T25: FALSE | U25: FALSE | V25: =IF(S25 > "10:30" + TIME(0,0,0),S25 - "10:30","")
D26: {=IFERROR(INDEX('Email Template'!P$8:P$72,MATCH(B26,'Email Template'!L$8:L$72,0)),"")} | E26: =IFERROR(INDEX(V$8:V$72,MATCH(B26,L$8:L$72,0)),"") | F26: =IFERROR(INDEX(W$8:W$72,MATCH(B26,L$8:L$72,0)),"") | K26: C | P26: {=IFERROR(INDEX('DSP RTS RETURNS '!A$14:A$38,MATCH(L26,'DSP RTS RETURNS '!B$14:B$38,0)),"")} | R26: {=IFERROR(INDEX('DSP RTS RETURNS '!AA$14:AA$38,MATCH(L26,'DSP RTS RETURNS '!B$14:B$38,0)),"")} | S26: =R26-Q26 -> 0 | T26: FALSE | U26: FALSE | V26: =IF(S26 > "10:30" + TIME(0,0,0),S26 - "10:30","")
D27: {=IFERROR(INDEX('Email Template'!P$8:P$72,MATCH(B27,'Email Template'!L$8:L$72,0)),"")} | E27: =IFERROR(INDEX(V$8:V$72,MATCH(B27,L$8:L$72,0)),"") | F27: =IFERROR(INDEX(W$8:W$72,MATCH(B27,L$8:L$72,0)),"") | K27: C | P27: {=IFERROR(INDEX('DSP RTS RETURNS '!A$14:A$38,MATCH(L27,'DSP RTS RETURNS '!B$14:B$38,0)),"")} | R27: {=IFERROR(INDEX('DSP RTS RETURNS '!AA$14:AA$38,MATCH(L27,'DSP RTS RETURNS '!B$14:B$38,0)),"")} | S27: =R27-Q27 -> 0 | T27: FALSE | U27: FALSE | V27: =IF(S27 > "10:30" + TIME(0,0,0),S27 - "10:30","")
D28: {=IFERROR(INDEX('Email Template'!P$8:P$72,MATCH(B28,'Email Template'!L$8:L$72,0)),"")} | E28: =IFERROR(INDEX(V$8:V$72,MATCH(B28,L$8:L$72,0)),"") | F28: =IFERROR(INDEX(W$8:W$72,MATCH(B28,L$8:L$72,0)),"") | K28: C | P28: {=IFERROR(INDEX('DSP RTS RETURNS '!A$14:A$38,MATCH(L28,'DSP RTS RETURNS '!B$14:B$38,0)),"")} | R28: {=IFERROR(INDEX('DSP RTS RETURNS '!AA$14:AA$38,MATCH(L28,'DSP RTS RETURNS '!B$14:B$38,0)),"")} | S28: =R28-Q28 -> 0 | T28: FALSE | U28: FALSE | V28: =IF(S28 > "10:30" + TIME(0,0,0),S28 - "10:30","")
D29: {=IFERROR(INDEX('Email Template'!P$8:P$72,MATCH(B29,'Email Template'!L$8:L$72,0)),"")} | E29: =IFERROR(INDEX(V$8:V$72,MATCH(B29,L$8:L$72,0)),"") | F29: =IFERROR(INDEX(W$8:W$72,MATCH(B29,L$8:L$72,0)),"") | K29: C | P29: {=IFERROR(INDEX('DSP RTS RETURNS '!A$14:A$38,MATCH(L29,'DSP RTS RETURNS '!B$14:B$38,0)),"")} | R29: {=IFERROR(INDEX('DSP RTS RETURNS '!AA$14:AA$38,MATCH(L29,'DSP RTS RETURNS '!B$14:B$38,0)),"")} | S29: =R29-Q29 -> 0 | T29: FALSE | U29: FALSE | V29: =IF(S29 > "10:30" + TIME(0,0,0),S29 - "10:30","")
D30: {=IFERROR(INDEX('Email Template'!P$8:P$72,MATCH(B30,'Email Template'!L$8:L$72,0)),"")} | E30: =IFERROR(INDEX(V$8:V$72,MATCH(B30,L$8:L$72,0)),"") | F30: =IFERROR(INDEX(W$8:W$72,MATCH(B30,L$8:L$72,0)),"") | K30: C | P30: {=IFERROR(INDEX('DSP RTS RETURNS '!A$14:A$38,MATCH(L30,'DSP RTS RETURNS '!B$14:B$38,0)),"")} | R30: {=IFERROR(INDEX('DSP RTS RETURNS '!AA$14:AA$38,MATCH(L30,'DSP RTS RETURNS '!B$14:B$38,0)),"")} | S30: =R30-Q30 -> 0 | T30: FALSE | U30: FALSE | V30: =IF(S30 > "10:30" + TIME(0,0,0),S30 - "10:30","")
... D45: {=IFERROR(INDEX('Email Template'!P$8:P$72,MATCH(B45,'Email Template'!L$8:L$72,0)),"")} | E45: =IFERROR(INDEX(V$8:V$72,MATCH(B45,L$8:L$72,0)),"") | F45: =IFERROR(INDEX(W$8:W$72,MATCH(B45,L$8:L$72,0)),"") | K45: 11 | P45: {=IFERROR(INDEX('DSP RTS RETURNS '!A$14:A$38,MATCH(L45,'DSP RTS RETURNS '!B$14:B$38,0)),"")} | R45: {=IFERROR(INDEX('DSP RTS RETURNS '!AA$14:AA$38,MATCH(L45,'DSP RTS RETURNS '!B$14:B$38,0)),"")} | S45: =R45-Q45 -> 0 | T45: FALSE | U45: FALSE | V45: =IF(S45 > "10:30" + TIME(0,0,0),S45 - "10:30","")
D46: {=IFERROR(INDEX('Email Template'!P$8:P$72,MATCH(B46,'Email Template'!L$8:L$72,0)),"")} | E46: =IFERROR(INDEX(V$8:V$72,MATCH(B46,L$8:L$72,0)),"") | F46: =IFERROR(INDEX(W$8:W$72,MATCH(B46,L$8:L$72,0)),"") | P46: {=IFERROR(INDEX('DSP RTS RETURNS '!A$14:A$38,MATCH(L46,'DSP RTS RETURNS '!B$14:B$38,0)),"")} | R46: {=IFERROR(INDEX('DSP RTS RETURNS '!AA$14:AA$38,MATCH(L46,'DSP RTS RETURNS '!B$14:B$38,0)),"")} | S46: =R46-Q46 -> 0 | T46: FALSE | U46: FALSE | V46: =IF(S46 > "10:30" + TIME(0,0,0),S46 - "10:30","")
D47: {=IFERROR(INDEX('Email Template'!P$8:P$72,MATCH(B47,'Email Template'!L$8:L$72,0)),"")} | E47: =IFERROR(INDEX(V$8:V$72,MATCH(B47,L$8:L$72,0)),"") | F47: =IFERROR(INDEX(W$8:W$72,MATCH(B47,L$8:L$72,0)),"") | P47: {=IFERROR(INDEX('DSP RTS RETURNS '!A$14:A$38,MATCH(L47,'DSP RTS RETURNS '!B$14:B$38,0)),"")} | R47: {=IFERROR(INDEX('DSP RTS RETURNS '!AA$14:AA$38,MATCH(L47,'DSP RTS RETURNS '!B$14:B$38,0)),"")} | S47: =R47-Q47 -> 0 | T47: FALSE | U47: FALSE | V47: =IF(S47 > "10:30" + TIME(0,0,0),S47 - "10:30","")
D48: {=IFERROR(INDEX('Email Template'!P$8:P$72,MATCH(B48,'Email Template'!L$8:L$72,0)),"")} | E48: =IFERROR(INDEX(V$8:V$72,MATCH(B48,L$8:L$72,0)),"") | F48: =IFERROR(INDEX(W$8:W$72,MATCH(B48,L$8:L$72,0)),"") | P48: {=IFERROR(INDEX('DSP RTS RETURNS '!A$14:A$38,MATCH(L48,'DSP RTS RETURNS '!B$14:B$38,0)),"")} | R48: {=IFERROR(INDEX('DSP RTS RETURNS '!AA$14:AA$38,MATCH(L48,'DSP RTS RETURNS '!B$14:B$38,0)),"")} | S48: =R48-Q48 -> 0 | T48: FALSE | U48: FALSE | V48: =IF(S48 > "10:30" + TIME(0,0,0),S48 - "10:30","")
D49: {=IFERROR(INDEX('Email Template'!P$8:P$72,MATCH(B49,'Email Template'!L$8:L$72,0)),"")} | E49: =IFERROR(INDEX(V$8:V$72,MATCH(B49,L$8:L$72,0)),"") | F49: =IFERROR(INDEX(W$8:W$72,MATCH(B49,L$8:L$72,0)),"") | P49: {=IFERROR(INDEX('DSP RTS RETURNS '!A$14:A$38,MATCH(L49,'DSP RTS RETURNS '!B$14:B$38,0)),"")} | R49: {=IFERROR(INDEX('DSP RTS RETURNS '!AA$14:AA$38,MATCH(L49,'DSP RTS RETURNS '!B$14:B$38,0)),"")} | S49: =R49-Q49 -> 0 | T49: FALSE | U49: FALSE | V49: =IF(S49 > "10:30" + TIME(0,0,0),S49 - "10:30","")
D50: {=IFERROR(INDEX('Email Template'!P$8:P$72,MATCH(B50,'Email Template'!L$8:L$72,0)),"")} | E50: =IFERROR(INDEX(V$8:V$72,MATCH(B50,L$8:L$72,0)),"") | F50: =IFERROR(INDEX(W$8:W$72,MATCH(B50,L$8:L$72,0)),"") | P50: {=IFERROR(INDEX('DSP RTS RETURNS '!A$14:A$38,MATCH(L50,'DSP RTS RETURNS '!B$14:B$38,0)),"")} | R50: {=IFERROR(INDEX('DSP RTS RETURNS '!AA$14:AA$38,MATCH(L50,'DSP RTS RETURNS '!B$14:B$38,0)),"")} | S50: =R50-Q50 -> 0 | T50: FALSE | U50: FALSE | V50: =IF(S50 > "10:30" + TIME(0,0,0),S50 - "10:30","")
D51: {=IFERROR(INDEX('Email Template'!P$8:P$72,MATCH(B51,'Email Template'!L$8:L$72,0)),"")} | E51: =IFERROR(INDEX(V$8:V$72,MATCH(B51,L$8:L$72,0)),"") | F51: =IFERROR(INDEX(W$8:W$72,MATCH(B51,L$8:L$72,0)),"") | P51: {=IFERROR(INDEX('DSP RTS RETURNS '!A$14:A$38,MATCH(L51,'DSP RTS RETURNS '!B$14:B$38,0)),"")} | R51: {=IFERROR(INDEX('DSP RTS RETURNS '!AA$14:AA$38,MATCH(L51,'DSP RTS RETURNS '!B$14:B$38,0)),"")} | S51: =R51-Q51 -> 0 | T51: FALSE | U51: FALSE | V51: =IF(S51 > "10:30" + TIME(0,0,0),S51 - "10:30","")
D52: {=IFERROR(INDEX('Email Template'!P$8:P$72,MATCH(B52,'Email Template'!L$8:L$72,0)),"")} | E52: =IFERROR(INDEX(V$8:V$72,MATCH(B52,L$8:L$72,0)),"") | F52: =IFERROR(INDEX(W$8:W$72,MATCH(B52,L$8:L$72,0)),"") | P52: {=IFERROR(INDEX('DSP RTS RETURNS '!A$14:A$38,MATCH(L52,'DSP RTS RETURNS '!B$14:B$38,0)),"")} | R52: {=IFERROR(INDEX('DSP RTS RETURNS '!AA$14:AA$38,MATCH(L52,'DSP RTS RETURNS '!B$14:B$38,0)),"")} | S52: =R52-Q52 -> 0 | T52: FALSE | U52: FALSE | V52: =IF(S52 > "10:30" + TIME(0,0,0),S52 - "10:30","")
D53: {=IFERROR(INDEX('Email Template'!P$8:P$72,MATCH(B53,'Email Template'!L$8:L$72,0)),"")} | E53: =IFERROR(INDEX(V$8:V$72,MATCH(B53,L$8:L$72,0)),"") | F53: =IFERROR(INDEX(W$8:W$72,MATCH(B53,L$8:L$72,0)),"") | P53: {=IFERROR(INDEX('DSP RTS RETURNS '!A$14:A$38,MATCH(L53,'DSP RTS RETURNS '!B$14:B$38,0)),"")} | R53: {=IFERROR(INDEX('DSP RTS RETURNS '!AA$14:AA$38,MATCH(L53,'DSP RTS RETURNS '!B$14:B$38,0)),"")} | S53: =R53-Q53 -> 0 | T53: FALSE | U53: FALSE | V53: =IF(S53 > "10:30" + TIME(0,0,0),S53 - "10:30","")
D54: {=IFERROR(INDEX('Email Template'!P$8:P$72,MATCH(B54,'Email Template'!L$8:L$72,0)),"")} | E54: =IFERROR(INDEX(V$8:V$72,MATCH(B54,L$8:L$72,0)),"") | F54: =IFERROR(INDEX(W$8:W$72,MATCH(B54,L$8:L$72,0)),"") | P54: {=IFERROR(INDEX('DSP RTS RETURNS '!A$14:A$38,MATCH(L54,'DSP RTS RETURNS '!B$14:B$38,0)),"")} | R54: {=IFERROR(INDEX('DSP RTS RETURNS '!AA$14:AA$38,MATCH(L54,'DSP RTS RETURNS '!B$14:B$38,0)),"")} | S54: =R54-Q54 -> 0 | T54: FALSE | U54: FALSE | V54: =IF(S54 > "10:30" + TIME(0,0,0),S54 - "10:30","")
D55: {=IFERROR(INDEX('Email Template'!P$8:P$72,MATCH(B55,'Email Template'!L$8:L$72,0)),"")} | E55: =IFERROR(INDEX(V$8:V$72,MATCH(B55,L$8:L$72,0)),"") | F55: =IFERROR(INDEX(W$8:W$72,MATCH(B55,L$8:L$72,0)),"") | P55: {=IFERROR(INDEX('DSP RTS RETURNS '!A$14:A$38,MATCH(L55,'DSP RTS RETURNS '!B$14:B$38,0)),"")} | R55: {=IFERROR(INDEX('DSP RTS RETURNS '!AA$14:AA$38,MATCH(L55,'DSP RTS RETURNS '!B$14:B$38,0)),"")} | S55: =R55-Q55 -> 0 | T55: FALSE | U55: FALSE | V55: =IF(S55 > "10:30" + TIME(0,0,0),S55 - "10:30","")
D56: {=IFERROR(INDEX('Email Template'!P$8:P$72,MATCH(B56,'Email Template'!L$8:L$72,0)),"")} | E56: =IFERROR(INDEX(V$8:V$72,MATCH(B56,L$8:L$72,0)),"") | F56: =IFERROR(INDEX(W$8:W$72,MATCH(B56,L$8:L$72,0)),"") | P56: {=IFERROR(INDEX('DSP RTS RETURNS '!A$14:A$38,MATCH(L56,'DSP RTS RETURNS '!B$14:B$38,0)),"")} | R56: {=IFERROR(INDEX('DSP RTS RETURNS '!AA$14:AA$38,MATCH(L56,'DSP RTS RETURNS '!B$14:B$38,0)),"")} | S56: =R56-Q56 -> 0 | T56: FALSE | U56: FALSE | V56: =IF(S56 > "10:30" + TIME(0,0,0),S56 - "10:30","")
...

Sheet Break Tracker 
A1: =TODAY() -> 46106 | F1: DVC6 DELE Break Tracker | S1: Total | T1: Other UPD | U1: Notes
F2: 1st break | K2: 2nd break | P2: 3rd break
A3: Cycle | B3: Route | C3: Driver | D3: Type | E3: Stop # | F3: Start time | G3: End time | H3: Duration | I3: Type | J3: Stop # | K3: Start time | L3: End time | M3: Duration | N3: Type | O3: Stop # | P3: Start time | Q3: End time | R3: Duration
H4: =G4-F4 -> 0 | M4: =L4-K4 -> 0 | R4: =Q4-P4 -> 0 | S4: =H4+M4+R4 -> 0
H5: =G5-F5 -> 0 | M5: =L5-K5 -> 0 | R5: =Q5-P5 -> 0 | S5: =H5+M5+R5 -> 0
H6: =G6-F6 -> 0 | M6: =L6-K6 -> 0 | R6: =Q6-P6 -> 0 | S6: =H6+M6+R6 -> 0
H7: =G7-F7 -> 0 | M7: =L7-K7 -> 0 | R7: =Q7-P7 -> 0 | S7: =H7+M7+R7 -> 0
H8: =G8-F8 -> 0 | M8: =L8-K8 -> 0 | R8: =Q8-P8 -> 0 | S8: =H8+M8+R8 -> 0
H9: =G9-F9 -> 0 | M9: =L9-K9 -> 0 | R9: =Q9-P9 -> 0 | S9: =H9+M9+R9 -> 0
H10: =G10-F10 -> 0 | M10: =L10-K10 -> 0 | R10: =Q10-P10 -> 0 | S10: =H10+M10+R10 -> 0
H11: =G11-F11 -> 0 | M11: =L11-K11 -> 0 | R11: =Q11-P11 -> 0 | S11: =H11+M11+R11 -> 0
H12: =G12-F12 -> 0 | M12: =L12-K12 -> 0 | R12: =Q12-P12 -> 0 | S12: =H12+M12+R12 -> 0
H13: =G13-F13 -> 0 | M13: =L13-K13 -> 0 | R13: =Q13-P13 -> 0 | S13: =H13+M13+R13 -> 0
H14: =G14-F14 -> 0 | M14: =L14-K14 -> 0 | R14: =Q14-P14 -> 0 | S14: =H14+M14+R14 -> 0
H15: =G15-F15 -> 0 | M15: =L15-K15 -> 0 | R15: =Q15-P15 -> 0 | S15: =H15+M15+R15 -> 0
... H60: =G60-F60 -> 0 | M60: =L60-K60 -> 0 | R60: =Q60-P60 -> 0 | S60: =H60+M60+R60 -> 0

Sheet Route Adherence
A1: Route Adherence check
A2: Cycle 1
A3: DA name | B3: Auto suggested | C3: Route | D3: 0.4375 | E3: 0.52083333 | F3: 0.60416667 | G3: Notes
A31: Cycle 2
A32: DA name | B32: Auto suggested | C32: Route | D32: 0.5625 | E32: 0.64583333 | F32: 0.72916667 | G32: Notes
